Traceback (most recent call last):
  File "C:\Users\elija\AppData\Local\Packages\PythonSoftwareFoundation.Python.3.11_qbz5n2kfra8p0\LocalCache\local-packages\Python311\site-packages\jupyter_cache\executors\utils.py", line 58, in single_nb_execution
    executenb(
  File "C:\Users\elija\AppData\Local\Packages\PythonSoftwareFoundation.Python.3.11_qbz5n2kfra8p0\LocalCache\local-packages\Python311\site-packages\nbclient\client.py", line 1314, in execute
    return NotebookClient(nb=nb, resources=resources, km=km, **kwargs).execute()
           ^^^^^^^^^^^^^^^^^^^^^^^^^^^^^^^^^^^^^^^^^^^^^^^^^^^^^^^^^^^^^^^^^^^^^
  File "C:\Users\elija\AppData\Local\Packages\PythonSoftwareFoundation.Python.3.11_qbz5n2kfra8p0\LocalCache\local-packages\Python311\site-packages\jupyter_core\utils\__init__.py", line 165, in wrapped
    return loop.run_until_complete(inner)
           ^^^^^^^^^^^^^^^^^^^^^^^^^^^^^^
  File "C:\Program Files\WindowsApps\PythonSoftwareFoundation.Python.3.11_3.11.2544.0_x64__qbz5n2kfra8p0\Lib\asyncio\base_events.py", line 654, in run_until_complete
    return future.result()
           ^^^^^^^^^^^^^^^
  File "C:\Users\elija\AppData\Local\Packages\PythonSoftwareFoundation.Python.3.11_qbz5n2kfra8p0\LocalCache\local-packages\Python311\site-packages\nbclient\client.py", line 709, in async_execute
    await self.async_execute_cell(
  File "C:\Users\elija\AppData\Local\Packages\PythonSoftwareFoundation.Python.3.11_qbz5n2kfra8p0\LocalCache\local-packages\Python311\site-packages\nbclient\client.py", line 1062, in async_execute_cell
    await self._check_raise_for_error(cell, cell_index, exec_reply)
  File "C:\Users\elija\AppData\Local\Packages\PythonSoftwareFoundation.Python.3.11_qbz5n2kfra8p0\LocalCache\local-packages\Python311\site-packages\nbclient\client.py", line 918, in _check_raise_for_error
    raise CellExecutionError.from_cell_and_msg(cell, exec_reply_content)
nbclient.exceptions.CellExecutionError: An error occurred while executing the following cell:
------------------
import epidemic_intelligence as ei
from google.oauth2 import service_account
from google.cloud import bigquery

credentials = service_account.Credentials.from_service_account_file('../../../credentials.json') # use the path to your credentials
project = 'net-data-viz-handbook' # use your project name
# Initialize a GC client
client = bigquery.Client(credentials=credentials, project=project)

table_name = 'importation_data.h1n1_proper' # str, name of bigquery table
destination = 'importation_data.h1n1_proper_simple' # str, name of place where simplified table will be stored

method = 'directional' # mbd, directional, mean, median, or ftvariance

source_column = 'source_basin'
target_column = 'target_basin'
value_column = 'importations'
compartment_column = 'compartment' 

ei.summarize_runs(client,
                     table_name,
                     destination,
                     method,
                     source_column,
                     target_column,
                     value_column,
                     compartment_column
)
------------------


[1;31m---------------------------------------------------------------------------[0m
[1;31mModuleNotFoundError[0m                       Traceback (most recent call last)
Cell [1;32mIn[1], line 1[0m
[1;32m----> 1[0m [38;5;28;01mimport[39;00m [38;5;21;01mepidemic_intelligence[39;00m [38;5;28;01mas[39;00m [38;5;21;01mei[39;00m
[0;32m      2[0m [38;5;28;01mfrom[39;00m [38;5;21;01mgoogle[39;00m[38;5;21;01m.[39;00m[38;5;21;01moauth2[39;00m [38;5;28;01mimport[39;00m service_account
[0;32m      3[0m [38;5;28;01mfrom[39;00m [38;5;21;01mgoogle[39;00m[38;5;21;01m.[39;00m[38;5;21;01mcloud[39;00m [38;5;28;01mimport[39;00m bigquery

[1;31mModuleNotFoundError[0m: No module named 'epidemic_intelligence'

